Workbook

Sheet 全台股
A1: ID | B1: Name | C1: Year | D1: Assets | E1: STD | F1: CPLTD | G1: LTD | H1: EBITDA | I1: Sales | J1: Sales_YOY | K1: FCF | L1: CapEx | M1: Int | N1: TIE | O1: CR | P1: FX | Q1: Industry
A2: 1101 | B2: 台泥 | C2: 2024 | D2: 593413647 | E2: 24292290 | F2: 9307637 | G2: 61287926 | H2: 44556263 | I2: 154606511 | J2: 0.4143 | K2: -7979225 | L2: -33603520 | M2: 0.2649 | N2: 5.35 | O2: 200.73 | P2: 2488775 | Q2: =_xlfn.XLOOKUP(A2,工作表1!$A:$A,工作表1!$Q:$Q) -> 水泥製造
A3: 1101 | B3: 台泥 | C3: 2023 | D3: 469438522 | E3: 20251073 | F3: 13859614 | G3: 36791733 | H3: 27184237 | I3: 109314335 | J3: -0.0405 | K3: 14445652 | L3: -24726266 | M3: 0.2759 | N3: 5.05 | O3: 210.95 | P3: -838432 | Q3: =_xlfn.XLOOKUP(A3,工作表1!$A:$A,工作表1!$Q:$Q) -> 水泥製造
A4: 1101 | B4: 台泥 | C4: 2022 | D4: 460808961 | E4: 22416812 | F4: 21511839 | G4: 42864736 | H4: 18043816 | I4: 113929706 | J4: 0.0644 | K4: -30522717 | L4: -23458453 | M4: 0.4447 | N4: 3.32 | O4: 233.51 | P4: 2088653 | Q4: =_xlfn.XLOOKUP(A4,工作表1!$A:$A,工作表1!$Q:$Q) -> 水泥製造
A5: 1102 | B5: 亞泥 | C5: 2024 | D5: 331827224 | E5: 26488506 | F5: 18871785 | G5: 8926787 | H5: 22257323 | I5: 81848827 | J5: -0.0087 | K5: 15731708 | L5: -4003258 | M5: 0.1192 | N5: 10.6 | O5: 146.4 | P5: 1397272 | Q5: =_xlfn.XLOOKUP(A5,工作表1!$A:$A,工作表1!$Q:$Q) -> 水泥製造
A6: 1102 | B6: 亞泥 | C6: 2023 | D6: 336726851 | E6: 29016580 | F6: 10219160 | G6: 9567454 | H6: 20464516 | I6: 82564009 | J6: -0.0939 | K6: 12791788 | L6: -4081969 | M6: 0.1418 | N6: 8.86 | O6: 147.6 | P6: -394244 | Q6: =_xlfn.XLOOKUP(A6,工作表1!$A:$A,工作表1!$Q:$Q) -> 水泥製造
A7: 1102 | B7: 亞泥 | C7: 2022 | D7: 324243127 | E7: 28692869 | F7: 1593990 | G7: 10415840 | H7: 21261387 | I7: 91122104 | J7: -0.031 | K7: 9086417 | L7: -2666315 | M7: 0.095 | N7: 12.73 | O7: 157.05 | P7: 1089038 | Q7: =_xlfn.XLOOKUP(A7,工作表1!$A:$A,工作表1!$Q:$Q) -> 水泥製造
A8: 1103 | B8: 嘉泥 | C8: 2024 | D8: 35078080 | E8: 885000 | F8: 1055745 | G8: 6879673 | H8: 1049811 | I8: 2985357 | J8: 0.0253 | K8: 1058475 | L8: -51631 | M8: 0.423 | N8: 2.79 | O8: 336.63 | P8: 46319 | Q8: =_xlfn.XLOOKUP(A8,工作表1!$A:$A,工作表1!$Q:$Q) -> 水泥製造
A9: 1103 | B9: 嘉泥 | C9: 2023 | D9: 36464334 | E9: 1356040 | F9: 571452 | G9: 7386018 | H9: 745243 | I9: 2911583 | J9: 0.2919 | K9: 219756 | L9: -51589 | M9: 0.7865 | N9: 1.41 | O9: 319.5 | P9: -52445 | Q9: =_xlfn.XLOOKUP(A9,工作表1!$A:$A,工作表1!$Q:$Q) -> 水泥製造
A10: 1103 | B10: 嘉泥 | C10: 2022 | D10: 36454234 | E10: 1673664 | F10: 933090 | G10: 7439628 | H10: 545575 | I10: 2253659 | J10: 0.015 | K10: 1671514 | L10: -55508 | M10: -4.4199 | N10: 0.28 | O10: 302.94 | P10: 208074 | Q10: =_xlfn.XLOOKUP(A10,工作表1!$A:$A,工作表1!$Q:$Q) -> 水泥製造
A11: 1104 | B11: 環泥 | C11: 2024 | D11: 29627506 | E11: 2100000 | F11: 0 | G11: 0 | H11: 2070596 | I11: 7953734 | J11: 0.0194 | K11: 948645 | L11: -179647 | M11: 0.0274 | N11: 43.09 | O11: 188.97 | P11: 0 | Q11: =_xlfn.XLOOKUP(A11,工作表1!$A:$A,工作表1!$Q:$Q) -> 水泥製造
A12: 1104 | B12: 環泥 | C12: 2023 | D12: 28189560 | E12: 1700000 | F12: 500000 | G12: 0 | H12: 2824162 | I12: 7802362 | J12: 0.1058 | K12: 477272 | L12: -195570 | M12: 0.0233 | N12: 47.39 | O12: 167.61 | P12: 0 | Q12: =_xlfn.XLOOKUP(A12,工作表1!$A:$A,工作表1!$Q:$Q) -> 水泥製造
A13: 1104 | B13: 環泥 | C13: 2022 | D13: 27811895 | E13: 2290000 | F13: 0 | G13: 0 | H13: 2603027 | I13: 7055789 | J13: 0.1607 | K13: 1903651 | L13: -320210 | M13: 0.0188 | N13: 58.19 | O13: 118.88 | P13: 0 | Q13: =_xlfn.XLOOKUP(A13,工作表1!$A:$A,工作表1!$Q:$Q) -> 水泥製造
... A373: 1526 | B373: 日馳 | C373: 2022 | D373: 2904399 | E373: 294560 | F373: 5326 | G373: 332505 | H373: 581227 | I373: 2197117 | J373: 0.164 | K373: 370695 | L373: -80994 | M373: 0.0249 | N373: 51.27 | O373: 183.91 | P373: 29889 | Q373: =_xlfn.XLOOKUP(A373,工作表1!$A:$A,工作表1!$Q:$Q) -> 自行車組件
A374: 1527 | B374: 鑽全 | C374: 2024 | D374: 5558752 | E374: 0 | F374: 0 | G374: 0 | H374: 682523 | I374: 3130242 | J374: 0.1243 | K374: 842032 | L374: -140094 | M374: 0 | O374: 591.17 | P374: 0 | Q374: =_xlfn.XLOOKUP(A374,工作表1!$A:$A,工作表1!$Q:$Q) -> 工具機
A375: 1527 | B375: 鑽全 | C375: 2023 | D375: 5288545 | E375: 0 | F375: 0 | G375: 0 | H375: 584941 | I375: 2784110 | J375: -0.2895 | K375: 512467 | L375: -105534 | M375: 0 | O375: 764.46 | P375: 0 | Q375: =_xlfn.XLOOKUP(A375,工作表1!$A:$A,工作表1!$Q:$Q) -> 工具機
A376: 1527 | B376: 鑽全 | C376: 2022 | D376: 5406694 | E376: 0 | F376: 0 | G376: 0 | H376: 1061051 | I376: 3918677 | J376: -0.1262 | K376: 377834 | L376: -43045 | M376: 0 | O376: 656.75 | P376: 0 | Q376: =_xlfn.XLOOKUP(A376,工作表1!$A:$A,工作表1!$Q:$Q) -> 工具機
A377: 1528 | B377: 恩德 | C377: 2024 | D377: 5305871 | E377: 1542608 | F377: 268122 | G377: 355633 | H377: 42020 | I377: 3672594 | J377: -0.0542 | K377: 207148 | L377: -113543 | M377: -0.5333 | N377: -1.57 | O377: 141.47 | P377: 9149 | Q377: =_xlfn.XLOOKUP(A377,工作表1!$A:$A,工作表1!$Q:$Q) -> 工具機
A378: 1528 | B378: 恩德 | C378: 2023 | D378: 5556368 | E378: 1473390 | F378: 221893 | G378: 457494 | H378: 188428 | I378: 3883131 | J378: 0.0248 | K378: -3345 | L378: -56035 | M378: 5.0485 | N378: 0.99 | O378: 156.08 | P378: 5002 | Q378: =_xlfn.XLOOKUP(A378,工作表1!$A:$A,工作表1!$Q:$Q) -> 工具機
A379: 1528 | B379: 恩德 | C379: 2022 | D379: 5559022 | E379: 1416518 | F379: 147649 | G379: 391208 | H379: 367330 | I379: 3789118 | J379: 0.0562 | K379: 178780 | L379: -117011 | M379: 0.2028 | N379: 6.6 | O379: 152.57 | P379: 48203 | Q379: =_xlfn.XLOOKUP(A379,工作表1!$A:$A,工作表1!$Q:$Q) -> 工具機
A380: 1529 | B380: 樂事綠能 | C380: 2024 | D380: 3384566 | E380: 275000 | F380: 62389 | G380: 816396 | H380: 143995 | I380: 696439 | J380: -0.0743 | K380: 86963 | L380: -200327 | M380: 7.1849 | N380: 0.9 | O380: 159.65 | P380: 0 | Q380: =_xlfn.XLOOKUP(A380,工作表1!$A:$A,工作表1!$Q:$Q) -> 電機
A381: 1529 | B381: 樂事綠能 | C381: 2023 | D381: 3137634 | E381: 171271 | F381: 63368 | G381: 777783 | H381: 269769 | I381: 752370 | J381: 1.6725 | K381: 12120 | L381: -244510 | M381: 0.1389 | N381: 7.81 | O381: 233.73 | P381: 0 | Q381: =_xlfn.XLOOKUP(A381,工作表1!$A:$A,工作表1!$Q:$Q) -> 電機
A382: 1529 | B382: 樂事綠能 | C382: 2022 | D382: 2999128 | E382: 240640 | F382: 47081 | G382: 699303 | H382: 121462 | I382: 281520 | J382: -0.1323 | K382: -388864 | L382: -476445 | M382: 0.2003 | N382: 6.08 | O382: 223.15 | P382: 221 | Q382: =_xlfn.XLOOKUP(A382,工作表1!$A:$A,工作表1!$Q:$Q) -> 電機
A383: 1530 | B383: 亞崴 | C383: 2024 | D383: 6393258 | E383: 1613983 | F383: 0 | G383: 0 | H383: 598714 | I383: 1917762 | J383: -0.188 | K383: 154770 | L383: -183694 | M383: 0.0665 | N383: 15.59 | O383: 166.88 | P383: 14778 | Q383: =_xlfn.XLOOKUP(A383,工作表1!$A:$A,工作表1!$Q:$Q) -> 工具機
A384: 1530 | B384: 亞崴 | C384: 2023 | D384: 5961891 | E384: 1576852 | F384: 0 | G384: 0 | H384: 382397 | I384: 2361917 | J384: -0.2382 | K384: 201950 | L384: -54542 | M384: 0.1513 | N384: 8.18 | O384: 155.93 | P384: -9215 | Q384: =_xlfn.XLOOKUP(A384,工作表1!$A:$A,工作表1!$Q:$Q) -> 工具機
A385: 1530 | B385: 亞崴 | C385: 2022 | D385: 6791798 | E385: 1954949 | F385: 0 | G385: 0 | H385: 603835 | I385: 3100517 | J385: -0.1461 | K385: 163337 | L385: -22340 | M385: 0.0703 | N385: 18.68 | O385: 140.01 | P385: 2219 | Q385: =_xlfn.XLOOKUP(A385,工作表1!$A:$A,工作表1!$Q:$Q) -> 工具機
A386: 1531 | B386: 高林股 | C386: 2024 | D386: 4371229 | E386: 100000 | F386: 0 | G386: 0 | H386: 188585 | I386: 1637783 | J386: 0.1529 | K386: -42814 | L386: -47070 | M386: 0.0265 | N386: 47.8 | O386: 805.97 | P386: 18550 | Q386: =_xlfn.XLOOKUP(A386,工作表1!$A:$A,工作表1!$Q:$Q) -> 紡織工具機
A387: 1531 | B387: 高林股 | C387: 2023 | D387: 4167691 | E387: 100000 | F387: 0 | G387: 0 | H387: 36591 | I387: 1420562 | J387: -0.4251 | K387: -87455 | L387: -211309 | M387: -0.088 | N387: -9.31 | O387: 796.73 | P387: -21161 | Q387: =_xlfn.XLOOKUP(A387,工作表1!$A:$A,工作表1!$Q:$Q) -> 紡織工具機
A388: 1531 | B388: 高林股 | C388: 2022 | D388: 4610206 | E388: 253549 | F388: 0 | G388: 0 | H388: 342054 | I388: 2471056 | J388: -0.1615 | K388: 160266 | L388: -22306 | M388: 0.0419 | N388: 33.06 | O388: 503.89 | P388: 16759 | Q388: =_xlfn.XLOOKUP(A388,工作表1!$A:$A,工作表1!$Q:$Q) -> 紡織工具機
... A409: 1539 | B409: 巨庭 | C409: 2022 | D409: 2648548 | E409: 256500 | F409: 74192 | G409: 321615 | H409: 542594 | I409: 2500079 | J409: -0.2045 | K409: 112896 | L409: -18412 | M409: 0.033 | N409: 36.73 | O409: 231.18 | P409: -4457 | Q409: =_xlfn.XLOOKUP(A409,工作表1!$A:$A,工作表1!$Q:$Q) -> 工具機
A410: 1540 | B410: 喬福 | C410: 2024 | D410: 1828680 | E410: 0 | F410: 0 | G410: 0 | H410: 234524 | I410: 498100 | J410: -0.1348 | K410: 80913 | L410: -4442 | M410: 0 | O410: 515.34 | P410: -73 | Q410: =_xlfn.XLOOKUP(A410,工作表1!$A:$A,工作表1!$Q:$Q) -> 工具機
A411: 1540 | B411: 喬福 | C411: 2023 | D411: 1718663 | E411: 0 | F411: 0 | G411: 0 | H411: 152768 | I411: 575699 | J411: 0.2164 | K411: 59792 | L411: -1653 | M411: 0 | O411: 494.49 | P411: -315 | Q411: =_xlfn.XLOOKUP(A411,工作表1!$A:$A,工作表1!$Q:$Q) -> 工具機
A412: 1540 | B412: 喬福 | C412: 2022 | D412: 1559314 | E412: 0 | F412: 0 | G412: 0 | H412: 143149 | I412: 473291 | J412: 0.3118 | K412: 23912 | L412: -1281 | M412: 0.0002 | N412: 7511.11 | O412: 711.35 | P412: 34624 | Q412: =_xlfn.XLOOKUP(A412,工作表1!$A:$A,工作表1!$Q:$Q) -> 工具機
A413: 1541 | B413: 錩泰 | C413: 2024 | D413: 3157599 | E413: 16000 | F413: 0 | G413: 0 | H413: 239701 | I413: 2988448 | J413: -0.1153 | K413: 221713 | L413: -12468 | M413: 0.1936 | N413: 6.13 | O413: 242.43 | P413: 30229 | Q413: =_xlfn.XLOOKUP(A413,工作表1!$A:$A,工作表1!$Q:$Q) -> 工具機
A414: 1541 | B414: 錩泰 | C414: 2023 | D414: 3978257 | E414: 569700 | F414: 0 | G414: 0 | H414: 282559 | I414: 3378030 | J414: -0.1674 | K414: 286884 | L414: -27926 | M414: 0.1449 | N414: 8.74 | O414: 175.02 | P414: -26 | Q414: =_xlfn.XLOOKUP(A414,工作表1!$A:$A,工作表1!$Q:$Q) -> 工具機
A415: 1541 | B415: 錩泰 | C415: 2022 | D415: 3611116 | E415: 544000 | F415: 0 | G415: 0 | H415: 495924 | I415: 4057447 | J415: -0.3459 | K415: 224559 | L415: -42134 | M415: 0.0775 | N415: 16.84 | O415: 193.21 | P415: 11700 | Q415: =_xlfn.XLOOKUP(A415,工作表1!$A:$A,工作表1!$Q:$Q) -> 工具機
A416: 1558 | B416: 伸興 | C416: 2024 | D416: 13140704 | E416: 906000 | F416: 107525 | G416: 616177 | H416: 1885894 | I416: 8337227 | J416: 0.1031 | K416: 1357424 | L416: -451003 | M416: 0.0234 | N416: 55.8 | O416: 225.4 | P416: 61794 | Q416: =_xlfn.XLOOKUP(A416,工作表1!$A:$A,工作表1!$Q:$Q) -> 紡織工具機
A417: 1558 | B417: 伸興 | C417: 2023 | D417: 11995154 | E417: 393000 | F417: 132525 | G417: 723702 | H417: 1424530 | I417: 7558277 | J417: 0.05 | K417: 1122626 | L417: -118606 | M417: 0.033 | N417: 33.98 | O417: 274.56 | P417: -44279 | Q417: =_xlfn.XLOOKUP(A417,工作表1!$A:$A,工作表1!$Q:$Q) -> 紡織工具機
A418: 1558 | B418: 伸興 | C418: 2022 | D418: 13244676 | E418: 1438492 | F418: 152454 | G418: 613905 | H418: 1290415 | I418: 7198245 | J418: -0.0676 | K418: 59030 | L418: -250643 | M418: 0.0437 | N418: 29.61 | O418: 212.28 | P418: 65111 | Q418: =_xlfn.XLOOKUP(A418,工作表1!$A:$A,工作表1!$Q:$Q) -> 紡織工具機
A419: 1560 | B419: 中砂 | C419: 2024 | D419: 11050863 | E419: 60500 | F419: 14383 | G419: 1078219 | H419: 1910886 | I419: 7019493 | J419: 0.1001 | K419: -678805 | L419: -348508 | M419: 0.0402 | N419: 30.23 | O419: 355.04 | P419: 26268 | Q419: =_xlfn.XLOOKUP(A419,工作表1!$A:$A,工作表1!$Q:$Q) -> 晶圓材料
...

Sheet 工作表1
A1: ID | B1: Name | C1: Year | D1: Assets | E1: STD | F1: CPLTD | G1: LTD | H1: EBITDA | I1: Sales | J1: Sales_YOY | K1: FCF | L1: CapEx | M1: Int | N1: TIE | O1: CR | P1: FX | Q1: Industry
A2: 1101 | B2: 台泥 | C2: 45627 | D2: 593413647 | E2: 24292290 | F2: 9307637 | G2: 61287926 | H2: 44556263 | I2: 154606511 | J2: 41.43 | K2: -7979225 | L2: -33603520 | M2: 26.49 | N2: 5.35 | O2: 200.73 | P2: 2488775 | Q2: 水泥製造
A3: 1102 | B3: 亞泥 | C3: 45627 | D3: 331827224 | E3: 26488506 | F3: 18871785 | G3: 8926787 | H3: 22257323 | I3: 81848827 | J3: -0.87 | K3: 15731708 | L3: -4003258 | M3: 11.92 | N3: 10.6 | O3: 146.4 | P3: 1397272 | Q3: 水泥製造
A4: 1103 | B4: 嘉泥 | C4: 45627 | D4: 35078080 | E4: 885000 | F4: 1055745 | G4: 6879673 | H4: 1049811 | I4: 2985357 | J4: 2.53 | K4: 1058475 | L4: -51631 | M4: 42.3 | N4: 2.79 | O4: 336.63 | P4: 46319 | Q4: 水泥製造
A5: 1104 | B5: 環泥 | C5: 45627 | D5: 29627506 | E5: 2100000 | F5: 0 | G5: 0 | H5: 2070596 | I5: 7953734 | J5: 1.94 | K5: 948645 | L5: -179647 | M5: 2.74 | N5: 43.09 | O5: 188.97 | P5: 0 | Q5: 水泥製造
A6: 1108 | B6: 幸福 | C6: 45627 | D6: 10431267 | E6: 1613112 | F6: 428000 | G6: 872500 | H6: 827725 | I6: 4867094 | J6: -4.47 | K6: 917334 | L6: -570866 | M6: 9.33 | N6: 13.18 | O6: 144.08 | P6: 251 | Q6: 水泥製造
A7: 1109 | B7: 信大 | C7: 45627 | D7: 11279234 | E7: 0 | F7: 0 | G7: 0 | H7: 1025055 | I7: 4656290 | J7: -25.62 | K7: 453026 | L7: -211756 | M7: 0.4 | N7: 336.87 | O7: 699.73 | P7: 82379 | Q7: 水泥製造
A8: 1110 | B8: 東泥 | C8: 45627 | D8: 12721937 | E8: 1266774 | F8: 50 | G8: 411320 | H8: 572398 | I8: 2872958 | J8: 26.37 | K8: 47092 | L8: -204807 | M8: 8.03 | N8: 14.42 | O8: 149.36 | P8: 0 | Q8: 水泥製造
A9: 1201 | B9: 味全 | C9: 45627 | D9: 17621082 | E9: 1821228 | F9: 18000 | G9: 2570000 | H9: 1888113 | I9: 23473804 | J9: 9.3 | K9: 241835 | L9: -734907 | M9: 23.57 | N9: 5.82 | O9: 103.91 | P9: 30508 | Q9: 飲料乳品
A10: 1203 | B10: 味王 | C10: 45627 | D10: 10278895 | E10: 777935 | F10: 126000 | G10: 0 | H10: 1373063 | I10: 6287463 | J10: -1.82 | K10: 630347 | L10: -129299 | M10: 2.56 | N10: 53.81 | O10: 268.69 | P10: 76917 | Q10: 其他食品
A11: 1210 | B11: 大成 | C11: 45627 | D11: 70755170 | E11: 16602929 | F11: 751521 | G11: 1669652 | H11: 9129286 | I11: 102749063 | J11: -7.52 | K11: 4177598 | L11: -4203213 | M11: 12.62 | N11: 10.06 | O11: 97.72 | P11: 507152 | Q11: 油脂飼料
A12: 1213 | B12: 大飲 | C12: 45627 | D12: 796039 | E12: 0 | F12: 0 | G12: 0 | H12: 546467 | I12: 190548 | J12: 57.87 | K12: -304537 | L12: -3305 | M12: 2.55 | N12: 41.41 | O12: 485.23 | P12: 3 | Q12: 飲料乳品
A13: 1215 | B13: 卜蜂 | C13: 45627 | D13: 29463806 | E13: 3398000 | F13: 1326311 | G13: 8644785 | H13: 3738582 | I13: 27957258 | J13: -4.12 | K13: 2086719 | L13: -2579743 | M13: 11.93 | N13: 10.42 | O13: 81.8 | P13: 3079 | Q13: 油脂飼料
... A125: 1526 | B125: 日馳 | C125: 45627 | D125: 2444138 | E125: 90955 | F125: 11100 | G125: 273543 | H125: 34555 | I125: 720682 | J125: -27.58 | K125: 134243 | L125: -18505 | M125: -56.92 | N125: -2.22 | O125: 472.75 | P125: 14688 | Q125: 自行車組件
A126: 1527 | B126: 鑽全 | C126: 45627 | D126: 5558752 | E126: 0 | F126: 0 | G126: 0 | H126: 682523 | I126: 3130242 | J126: 12.43 | K126: 842032 | L126: -140094 | M126: 0 | O126: 591.17 | P126: 0 | Q126: 工具機
A127: 1528 | B127: 恩德 | C127: 45627 | D127: 5305871 | E127: 1542608 | F127: 268122 | G127: 355633 | H127: 42020 | I127: 3672594 | J127: -5.42 | K127: 207148 | L127: -113543 | M127: -53.33 | N127: -1.57 | O127: 141.47 | P127: 9149 | Q127: 工具機
A128: 1529 | B128: 樂事綠能 | C128: 45627 | D128: 3384566 | E128: 275000 | F128: 62389 | G128: 816396 | H128: 143995 | I128: 696439 | J128: -7.43 | K128: 86963 | L128: -200327 | M128: 718.49 | N128: 0.9 | O128: 159.65 | P128: 0 | Q128: 電機
A129: 1530 | B129: 亞崴 | C129: 45627 | D129: 6393258 | E129: 1613983 | F129: 0 | G129: 0 | H129: 598714 | I129: 1917762 | J129: -18.8 | K129: 154770 | L129: -183694 | M129: 6.65 | N129: 15.59 | O129: 166.88 | P129: 14778 | Q129: 工具機
A130: 1531 | B130: 高林股 | C130: 45627 | D130: 4371229 | E130: 100000 | F130: 0 | G130: 0 | H130: 188585 | I130: 1637783 | J130: 15.29 | K130: -42814 | L130: -47070 | M130: 2.65 | N130: 47.8 | O130: 805.97 | P130: 18550 | Q130: 紡織工具機
A131: 1532 | B131: 勤美 | C131: 45627 | D131: 52845077 | E131: 12260016 | F131: 1385893 | G131: 7637096 | H131: 3276749 | I131: 18019849 | J131: 2.27 | K131: 1676496 | L131: -1264655 | M131: 20.4 | N131: 5.92 | O131: 141.34 | P131: 121003 | Q131: 模具零件
A132: 1533 | B132: 車王電 | C132: 45627 | D132: 8624480 | E132: 1396649 | F132: 1766027 | G132: 1137247 | H132: 138072 | I132: 3345244 | J132: -16.44 | K132: 1156989 | L132: -86619 | M132: -84.87 | N132: -0.86 | O132: 119.56 | P132: 140029 | Q132: 汽車組件
A133: 1535 | B133: 中宇 | C133: 45627 | D133: 7157430 | E133: 50000 | F133: 0 | G133: 0 | H133: 706115 | I133: 10858807 | J133: 11.27 | K133: 725055 | L133: -166971 | M133: 0.45 | N133: 278.16 | O133: 135.55 | P133: 20985 | Q133: 機電工程
A134: 1536 | B134: 和大 | C134: 45627 | D134: 22442497 | E134: 2834642 | F134: 1544738 | G134: 5242253 | H134: 1134470 | I134: 5774470 | J134: -12.5 | K134: 500341 | L134: -526174 | M134: 53.54 | N134: 2.28 | O134: 112.22 | P134: 76331 | Q134: 汽車組件
A135: 1537 | B135: 廣隆 | C135: 45627 | D135: 6317970 | E135: 48614 | F135: 0 | G135: 0 | H135: 1447085 | I135: 8137839 | J135: 26.82 | K135: 425496 | L135: -121509 | M135: 0.06 | N135: 2187.63 | O135: 455.18 | P135: 172836 | Q135: 二次電池
A136: 1538 | B136: 正峰 | C136: 45627 | D136: 271904 | E136: 7055 | F136: 0 | G136: 0 | H136: -39442 | I136: 112684 | J136: -42.04 | K136: -12098 | L136: -8508 | M136: -0.92 | N136: -105.19 | O136: 269.36 | P136: 21958 | Q136: 工具機
A137: 1539 | B137: 巨庭 | C137: 45627 | D137: 2253146 | E137: 80000 | F137: 28831 | G137: 195342 | H137: 175160 | I137: 1338821 | J137: -12.69 | K137: 168514 | L137: -21276 | M137: 6.7 | N137: 18.67 | O137: 272.12 | P137: 59 | Q137: 工具機
A138: 1540 | B138: 喬福 | C138: 45627 | D138: 1828680 | E138: 0 | F138: 0 | G138: 0 | H138: 234524 | I138: 498100 | J138: -13.48 | K138: 80913 | L138: -4442 | M138: 0 | O138: 515.34 | P138: -73 | Q138: 工具機
A139: 1541 | B139: 錩泰 | C139: 45627 | D139: 3157599 | E139: 16000 | F139: 0 | G139: 0 | H139: 239701 | I139: 2988448 | J139: -11.53 | K139: 221713 | L139: -12468 | M139: 19.36 | N139: 6.13 | O139: 242.43 | P139: 30229 | Q139: 工具機
A140: 1558 | B140: 伸興 | C140: 45627 | D140: 13140704 | E140: 906000 | F140: 107525 | G140: 616177 | H140: 1885894 | I140: 8337227 | J140: 10.31 | K140: 1357424 | L140: -451003 | M140: 2.34 | N140: 55.8 | O140: 225.4 | P140: 61794 | Q140: 紡織工具機
A141: 1560 | B141: 中砂 | C141: 45627 | D141: 11050863 | E141: 60500 | F141: 14383 | G141: 1078219 | H141: 1910886 | I141: 7019493 | J141: 10.01 | K141: -678805 | L141: -348508 | M141: 4.02 | N141: 30.23 | O141: 355.04 | P141: 26268 | Q141: 晶圓材料
A142: 1563 | B142: 巧新 | C142: 45627 | D142: 17519544 | E142: 1003535 | F142: 1027626 | G142: 4260544 | H142: 2017197 | I142: 7473579 | J142: -3.93 | K142: 219882 | L142: -487406 | M142: 17.82 | N142: 7.01 | O142: 273.06 | P142: -1036 | Q142: 汽車組件
A143: 1565 | B143: 精華 | C143: 45627 | D143: 8100886 | E143: 0 | F143: 103132 | G143: 186107 | H143: 1232467 | I143: 4550058 | J143: 3.55 | K143: 536490 | L143: -93115 | M143: 1.18 | N143: 106.91 | O143: 343.22 | P143: 64 | Q143: 輔助與彌補
A144: 1568 | B144: 倉佑 | C144: 45627 | D144: 2326550 | E144: 0 | F144: 55034 | G144: 65078 | H144: 297230 | I144: 1049324 | J144: -12.05 | K144: 369363 | L144: -175279 | M144: 2.43 | N144: 53.37 | O144: 278.55 | P144: -4003 | Q144: 汽車組件
A145: 1569 | B145: 濱川 | C145: 45627 | D145: 6400654 | E145: 1215326 | F145: 175467 | G145: 633303 | H145: 290312 | I145: 3103113 | J145: -13.93 | K145: 379177 | L145: -453465 | M145: -19.18 | N145: -4.78 | O145: 123.61 | P145: 106005 | Q145: 機殼
A146: 1570 | B146: 力肯 | C146: 45627 | D146: 1206637 | E146: 0 | F146: 0 | G146: 0 | H146: 152452 | I146: 730104 | J146: 85.47 | K146: 23292 | L146: -2177 | M146: 0.22 | N146: 544.78 | O146: 522.05 | P146: 244 | Q146: 工具機
A147: 1580 | B147: 新麥 | C147: 45627 | D147: 4466841 | E147: 0 | F147: 16561 | G147: 0 | H147: 1215754 | I147: 4792059 | J147: 6.52 | K147: 533964 | L147: -179694 | M147: 0.18 | N147: 810.27 | O147: 272.86 | P147: 31614 | Q147: 儀器設備
A148: 1582 | B148: 信錦 | C148: 45627 | D148: 13180799 | E148: 1704290 | F148: 21650 | G148: 173119 | H148: 2125830 | I148: 9404071 | J148: 7.24 | K148: 44926 | L148: -236091 | M148: 4.26 | N148: 36.54 | O148: 224.77 | P148: 110468 | Q148: 沖壓零組件
A149: 1583 | B149: 程泰 | C149: 45627 | D149: 14851237 | E149: 2986248 | F149: 77450 | G149: 996063 | H149: 1853535 | I149: 4422922 | J149: -16.84 | K149: -351072 | L149: -367515 | M149: 5.33 | N149: 19.75 | O149: 219.25 | P149: 64801 | Q149: 工具機
A150: 1584 | B150: 精剛 | C150: 45627 | D150: 7860166 | E150: 1166735 | F150: 16667 | G150: 1039967 | H150: 528632 | I150: 2880076 | J150: 4.79 | K150: -839591 | L150: -1842068 | M150: 13.33 | N150: 8.82 | O150: 230.2 | P150: 0 | Q150: 不鏽鋼
... A206: 1781 | B206: 合世 | C206: 45627 | D206: 817262 | E206: 0 | F206: 12612 | G206: 6306 | H206: 55630 | I206: 706388 | J206: 17.5 | K206: -165526 | L206: -3105 | M206: 12.53 | N206: 9.52 | O206: 262.05 | P206: 4075 | Q206: 診斷與監測
...
